use std::io::Error;

pub fn run() -> Result<(), Error> {
    let _ = task1();
    let _ = task2();

    println!("Completed solutions for Day 2!");

    Ok(())
}

fn task1() -> Result<(), Error> {
    println!("Computing solution for task 1 of Day 2...");
    Ok(())
}
fn task2() -> Result<(), Error> {
    println!("Computing solution for task 2 of Day 2...");
    Ok(())
}
